2025-07-25 10:57:05,572 - src.utils.file_utils - ERROR - main:61 - Unexpected error: 'MainWindow' object has no attribute 'status_label'
Traceback (most recent call last):
  File "C:\Users\aldri\Downloads\qr\src\gui\tabs\logs_tab.py", line 202, in _load_log_content
    self._apply_filter()
  File "C:\Users\aldri\Downloads\qr\src\gui\tabs\logs_tab.py", line 263, in _apply_filter
    self._update_status(f"Showing {len(self.filtered_entries)} of {len(self.log_entries)} entries")
  File "C:\Users\aldri\Downloads\qr\src\gui\tabs\logs_tab.py", line 406, in _update_status
    self.callbacks['update_status'](message)
  File "C:\Users\aldri\Downloads\qr\src\gui\main_window.py", line 561, in update_status
    self.status_label.configure(text=message)
    ^^^^^^^^^^^^^^^^^
AttributeError: 'MainWindow' object has no attribute 'status_label'. Did you mean: 'status_bar'?

During handling of the above exception, another exception occurred:

Traceback (most recent call last):
  File "C:\Users\aldri\Downloads\qr\src\gui\tabs\logs_tab.py", line 180, in _load_log_files
    self._load_log_content(self.log_files[0])
  File "C:\Users\aldri\Downloads\qr\src\gui\tabs\logs_tab.py", line 206, in _load_log_content
    self._update_status(f"Error loading log content: {str(e)}")
  File "C:\Users\aldri\Downloads\qr\src\gui\tabs\logs_tab.py", line 406, in _update_status
    self.callbacks['update_status'](message)
  File "C:\Users\aldri\Downloads\qr\src\gui\main_window.py", line 561, in update_status
    self.status_label.configure(text=message)
    ^^^^^^^^^^^^^^^^^
AttributeError: 'MainWindow' object has no attribute 'status_label'. Did you mean: 'status_bar'?

During handling of the above exception, another exception occurred:

Traceback (most recent call last):
  File "C:\Users\aldri\Downloads\qr\main.py", line 32, in main
    main_window = MainWindow(root, app_manager)
                  ^^^^^^^^^^^^^^^^^^^^^^^^^^^^^
  File "C:\Users\aldri\Downloads\qr\src\gui\main_window.py", line 64, in __init__
    self.setup_gui()
  File "C:\Users\aldri\Downloads\qr\src\gui\main_window.py", line 140, in setup_gui
    self._create_main_content(self.main_container)
  File "C:\Users\aldri\Downloads\qr\src\gui\main_window.py", line 301, in _create_main_content
    self._create_logs_tab(logs_frame)
  File "C:\Users\aldri\Downloads\qr\src\gui\main_window.py", line 545, in _create_logs_tab
    self.logs_tab = LogsTab(parent, self.app_manager, callbacks)
                    ^^^^^^^^^^^^^^^^^^^^^^^^^^^^^^^^^^^^^^^^^^^^
  File "C:\Users\aldri\Downloads\qr\src\gui\tabs\logs_tab.py", line 23, in __init__
    self._load_log_files()
  File "C:\Users\aldri\Downloads\qr\src\gui\tabs\logs_tab.py", line 183, in _load_log_files
    self._update_status(f"Error loading log files: {str(e)}")
  File "C:\Users\aldri\Downloads\qr\src\gui\tabs\logs_tab.py", line 406, in _update_status
    self.callbacks['update_status'](message)
  File "C:\Users\aldri\Downloads\qr\src\gui\main_window.py", line 561, in update_status
    self.status_label.configure(text=message)
    ^^^^^^^^^^^^^^^^^
AttributeError: 'MainWindow' object has no attribute 'status_label'. Did you mean: 'status_bar'?
2025-07-25 11:02:00,253 - src.utils.file_utils - ERROR - log_error:105 - Error connecting to spreadsheet: 'GoogleSheetsManager' object has no attribute 'connect_to_sheets'
2025-07-25 11:18:38,338 - src.utils.file_utils - ERROR - main:61 - Unexpected error: 'sm'
Traceback (most recent call last):
  File "C:\Users\aldri\Downloads\qr\main.py", line 32, in main
    main_window = MainWindow(root, app_manager)
                  ^^^^^^^^^^^^^^^^^^^^^^^^^^^^^
  File "C:\Users\aldri\Downloads\qr\src\gui\main_window.py", line 64, in __init__
    self.setup_gui()
  File "C:\Users\aldri\Downloads\qr\src\gui\main_window.py", line 142, in setup_gui
    self._create_main_content(self.main_container)
  File "C:\Users\aldri\Downloads\qr\src\gui\main_window.py", line 303, in _create_main_content
    self._create_logs_tab(logs_frame)
  File "C:\Users\aldri\Downloads\qr\src\gui\main_window.py", line 549, in _create_logs_tab
    self.logs_tab = LogsTab(parent, self.app_manager, callbacks)
                    ^^^^^^^^^^^^^^^^^^^^^^^^^^^^^^^^^^^^^^^^^^^^
  File "C:\Users\aldri\Downloads\qr\src\gui\tabs\logs_tab.py", line 22, in __init__
    self._create_logs_interface()
  File "C:\Users\aldri\Downloads\qr\src\gui\tabs\logs_tab.py", line 68, in _create_logs_interface
    self.filter_entry.pack(side=tk.LEFT, padx=(COMPONENT_SPACING['form_field_margin'], COMPONENT_SPACING['sm']))
                                                                                       ~~~~~~~~~~~~~~~~~^^^^^^
KeyError: 'sm'
2025-07-25 11:19:24,669 - src.utils.file_utils - ERROR - main:61 - Unexpected error: 'sm'
Traceback (most recent call last):
  File "C:\Users\aldri\Downloads\qr\main.py", line 32, in main
    main_window = MainWindow(root, app_manager)
                  ^^^^^^^^^^^^^^^^^^^^^^^^^^^^^
  File "C:\Users\aldri\Downloads\qr\src\gui\main_window.py", line 64, in __init__
    self.setup_gui()
  File "C:\Users\aldri\Downloads\qr\src\gui\main_window.py", line 142, in setup_gui
    self._create_main_content(self.main_container)
  File "C:\Users\aldri\Downloads\qr\src\gui\main_window.py", line 303, in _create_main_content
    self._create_logs_tab(logs_frame)
  File "C:\Users\aldri\Downloads\qr\src\gui\main_window.py", line 549, in _create_logs_tab
    self.logs_tab = LogsTab(parent, self.app_manager, callbacks)
                    ^^^^^^^^^^^^^^^^^^^^^^^^^^^^^^^^^^^^^^^^^^^^
  File "C:\Users\aldri\Downloads\qr\src\gui\tabs\logs_tab.py", line 22, in __init__
    self._create_logs_interface()
  File "C:\Users\aldri\Downloads\qr\src\gui\tabs\logs_tab.py", line 68, in _create_logs_interface
    self.filter_entry.pack(side=tk.LEFT, padx=(COMPONENT_SPACING['form_field_margin'], COMPONENT_SPACING['sm']))
                                                                                       ~~~~~~~~~~~~~~~~~^^^^^^
KeyError: 'sm'
2025-07-25 11:21:28,321 - src.utils.file_utils - ERROR - main:61 - Unexpected error: 'sm'
Traceback (most recent call last):
  File "C:\Users\aldri\Downloads\qr\main.py", line 32, in main
    main_window = MainWindow(root, app_manager)
                  ^^^^^^^^^^^^^^^^^^^^^^^^^^^^^
  File "C:\Users\aldri\Downloads\qr\src\gui\main_window.py", line 64, in __init__
    self.setup_gui()
  File "C:\Users\aldri\Downloads\qr\src\gui\main_window.py", line 142, in setup_gui
    self._create_main_content(self.main_container)
  File "C:\Users\aldri\Downloads\qr\src\gui\main_window.py", line 303, in _create_main_content
    self._create_logs_tab(logs_frame)
  File "C:\Users\aldri\Downloads\qr\src\gui\main_window.py", line 549, in _create_logs_tab
    self.logs_tab = LogsTab(parent, self.app_manager, callbacks)
                    ^^^^^^^^^^^^^^^^^^^^^^^^^^^^^^^^^^^^^^^^^^^^
  File "C:\Users\aldri\Downloads\qr\src\gui\tabs\logs_tab.py", line 22, in __init__
    self._create_logs_interface()
  File "C:\Users\aldri\Downloads\qr\src\gui\tabs\logs_tab.py", line 68, in _create_logs_interface
    self.filter_entry.pack(side=tk.LEFT, padx=(COMPONENT_SPACING['form_field_margin'], COMPONENT_SPACING['sm']))
                                                                                       ~~~~~~~~~~~~~~~~~^^^^^^
KeyError: 'sm'
2025-07-25 11:26:17,193 - src.utils.file_utils - ERROR - main:61 - Unexpected error: 'sm'
Traceback (most recent call last):
  File "C:\Users\aldri\Downloads\qr\main.py", line 32, in main
    main_window = MainWindow(root, app_manager)
                  ^^^^^^^^^^^^^^^^^^^^^^^^^^^^^
  File "C:\Users\aldri\Downloads\qr\src\gui\main_window.py", line 64, in __init__
    self.setup_gui()
  File "C:\Users\aldri\Downloads\qr\src\gui\main_window.py", line 142, in setup_gui
    self._create_main_content(self.main_container)
  File "C:\Users\aldri\Downloads\qr\src\gui\main_window.py", line 303, in _create_main_content
    self._create_logs_tab(logs_frame)
  File "C:\Users\aldri\Downloads\qr\src\gui\main_window.py", line 549, in _create_logs_tab
    self.logs_tab = LogsTab(parent, self.app_manager, callbacks)
                    ^^^^^^^^^^^^^^^^^^^^^^^^^^^^^^^^^^^^^^^^^^^^
  File "C:\Users\aldri\Downloads\qr\src\gui\tabs\logs_tab.py", line 22, in __init__
    self._create_logs_interface()
  File "C:\Users\aldri\Downloads\qr\src\gui\tabs\logs_tab.py", line 68, in _create_logs_interface
    self.filter_entry.pack(side=tk.LEFT, padx=(COMPONENT_SPACING['form_field_margin'], COMPONENT_SPACING['sm']))
                                                                                       ~~~~~~~~~~~~~~~~~^^^^^^
KeyError: 'sm'
2025-07-25 12:27:52,786 - src.utils.file_utils - ERROR - main:61 - Unexpected error: 'QRScannerApp' object has no attribute 'check_credentials'
Traceback (most recent call last):
  File "C:\Users\aldri\Downloads\qr\main.py", line 32, in main
    main_window = MainWindow(root, app_manager)
                  ^^^^^^^^^^^^^^^^^^^^^^^^^^^^^
  File "C:\Users\aldri\Downloads\qr\src\gui\main_window.py", line 36, in __init__
    self.setup_gui()
  File "C:\Users\aldri\Downloads\qr\src\gui\main_window.py", line 85, in setup_gui
    self._create_main_content(self.main_container)
  File "C:\Users\aldri\Downloads\qr\src\gui\main_window.py", line 127, in _create_main_content
    self._create_settings_tab(settings_frame)
  File "C:\Users\aldri\Downloads\qr\src\gui\main_window.py", line 184, in _create_settings_tab
    self.settings_tab = SettingsTab(parent, self.app_manager, callbacks)
                        ^^^^^^^^^^^^^^^^^^^^^^^^^^^^^^^^^^^^^^^^^^^^^^^^
  File "C:\Users\aldri\Downloads\qr\src\gui\tabs\settings_tab.py", line 23, in __init__
    self._check_initial_status()
  File "C:\Users\aldri\Downloads\qr\src\gui\tabs\settings_tab.py", line 129, in _check_initial_status
    if self.app_manager.check_credentials():
       ^^^^^^^^^^^^^^^^^^^^^^^^^^^^^^^^^^
AttributeError: 'QRScannerApp' object has no attribute 'check_credentials'. Did you mean: 'setup_credentials'?
2025-07-25 12:29:15,233 - src.utils.file_utils - ERROR - main:61 - Unexpected error: 'NoneType' object has no attribute 'is_connected'
Traceback (most recent call last):
  File "C:\Users\aldri\Downloads\qr\main.py", line 32, in main
    main_window = MainWindow(root, app_manager)
                  ^^^^^^^^^^^^^^^^^^^^^^^^^^^^^
  File "C:\Users\aldri\Downloads\qr\src\gui\main_window.py", line 36, in __init__
    self.setup_gui()
  File "C:\Users\aldri\Downloads\qr\src\gui\main_window.py", line 85, in setup_gui
    self._create_main_content(self.main_container)
  File "C:\Users\aldri\Downloads\qr\src\gui\main_window.py", line 127, in _create_main_content
    self._create_settings_tab(settings_frame)
  File "C:\Users\aldri\Downloads\qr\src\gui\main_window.py", line 184, in _create_settings_tab
    self.settings_tab = SettingsTab(parent, self.app_manager, callbacks)
                        ^^^^^^^^^^^^^^^^^^^^^^^^^^^^^^^^^^^^^^^^^^^^^^^^
  File "C:\Users\aldri\Downloads\qr\src\gui\tabs\settings_tab.py", line 23, in __init__
    self._check_initial_status()
  File "C:\Users\aldri\Downloads\qr\src\gui\tabs\settings_tab.py", line 138, in _check_initial_status
    if self.app_manager.is_sheets_connected():
       ^^^^^^^^^^^^^^^^^^^^^^^^^^^^^^^^^^^^^^
  File "C:\Users\aldri\Downloads\qr\src\core\app_manager.py", line 434, in is_sheets_connected
    return self.sheets_manager.is_connected()
           ^^^^^^^^^^^^^^^^^^^^^^^^^^^^^^^^
AttributeError: 'NoneType' object has no attribute 'is_connected'
2025-07-25 13:30:23,599 - src.utils.file_utils - ERROR - main:61 - Unexpected error: unknown option "-bg"
Traceback (most recent call last):
  File "C:\Users\aldri\Downloads\qr\main.py", line 32, in main
    main_window = MainWindow(root, app_manager)
                  ^^^^^^^^^^^^^^^^^^^^^^^^^^^^^
  File "C:\Users\aldri\Downloads\qr\src\gui\main_window.py", line 37, in __init__
    self.setup_gui()
  File "C:\Users\aldri\Downloads\qr\src\gui\main_window.py", line 86, in setup_gui
    self._create_main_content(self.main_container)
  File "C:\Users\aldri\Downloads\qr\src\gui\main_window.py", line 133, in _create_main_content
    self._create_history_tab(history_frame)
  File "C:\Users\aldri\Downloads\qr\src\gui\main_window.py", line 193, in _create_history_tab
    self.history_tab = HistoryTab(parent, self.app_manager, callbacks)
                       ^^^^^^^^^^^^^^^^^^^^^^^^^^^^^^^^^^^^^^^^^^^^^^^
  File "C:\Users\aldri\Downloads\qr\src\gui\tabs\history_tab.py", line 24, in __init__
    self._create_history_interface()
  File "C:\Users\aldri\Downloads\qr\src\gui\tabs\history_tab.py", line 61, in _create_history_interface
    self.history_tree = ttk.Treeview(tree_frame, bg=THEME_COLORS['background'], columns=columns, show='headings', height=15)
                        ^^^^^^^^^^^^^^^^^^^^^^^^^^^^^^^^^^^^^^^^^^^^^^^^^^^^^^^^^^^^^^^^^^^^^^^^^^^^^^^^^^^^^^^^^^^^^^^^^^^^
  File "C:\Program Files\WindowsApps\PythonSoftwareFoundation.Python.3.12_3.12.2800.0_x64__qbz5n2kfra8p0\Lib\tkinter\ttk.py", line 1180, in __init__
    Widget.__init__(self, master, "ttk::treeview", kw)
  File "C:\Program Files\WindowsApps\PythonSoftwareFoundation.Python.3.12_3.12.2800.0_x64__qbz5n2kfra8p0\Lib\tkinter\ttk.py", line 527, in __init__
    tkinter.Widget.__init__(self, master, widgetname, kw=kw)
  File "C:\Program Files\WindowsApps\PythonSoftwareFoundation.Python.3.12_3.12.2800.0_x64__qbz5n2kfra8p0\Lib\tkinter\__init__.py", line 2661, in __init__
    self.tk.call(
_tkinter.TclError: unknown option "-bg"
